Workbook

Sheet Sheet1
A1: Overall collection performance
A2: Festac vs Okota vs Cele
A3: Compliant vs non-compliant
A4: Ghost vs Original
A5: Riders with high balances
A6: Riders with poor repayment performance
A7: Location performance

Sheet project_1_mobility_operations_d
A1: start_date | B1: No_of_Days | C1: Total contract amount | D1: exp_daily_rep | E1: exp_weekly-pay | F1: down_payment | G1: Due today | H1: unique_id | I1: Status | J1: number_plate | K1: full_name | L1: account_number | M1: Total Received | N1: Paid week 1 | O1: Outstanding | P1: Remaining balance | Q1: Asset status | R1: Location | S1: Payment progress | T1: Payment rate | U1: Week 1 payment rate | V1: Days behind | W1: Repayment performance Category | X1: Rider status
A2: 45880 | B2: =NETWORKDAYS.INTL(A3,TODAY(),11) -> 474 | C2: 6000000 | D2: 10000 | E2: =D2*6 -> 60000 | F2: 50000 | G2: =B2*D2 -> 4740000 | H2: MOVE1000000 | I2: Active | J2: KTU96LM | K2: Tochukwu Bello | L2: 1000000000 | M2: 3111227 | N2: 38500 | O2: =G2-M2 -> 1628773 | P2: =C2-M2 -> 2888773 | Q2: =IF(O2>15000,"Non-compliant","Compliant") -> Non-compliant | R2: Festac | S2: =M2/C2 -> 0.51853783 | T2: =M2/G2 -> 0.656377 | U2: =N2/E2 -> 0.64166667 | V2: =O2/D2 -> 162.8773 | W2: =IF(T2>=0.9,"Good",IF(T2>=0.7,"Needs Monitoring","Poor")) -> Poor | X2: Original
A3: 45725 | B3: =NETWORKDAYS.INTL(A4,TODAY(),11) -> 353 | C3: 6000000 | D3: 10000 | E3: =D3*6 -> 60000 | F3: 50000 | G3: =B3*D3 -> 3530000 | H3: MOVE1000001 | I3: Active | J3: MUS35LM | K3: Tochukwu Williams | L3: 1000000001 | M3: 3405943 | N3: 36000 | O3: =G3-M3 -> 124057 | P3: =C3-M3 -> 2594057 | Q3: =IF(O3>15000,"Non-compliant","Compliant") -> Non-compliant | R3: Festac | S3: =M3/C3 -> 0.56765717 | T3: =M3/G3 -> 0.96485637 | U3: =N3/E3 -> 0.6 | V3: =O3/D3 -> 12.4057 | W3: =IF(T3>=0.9,"Good",IF(T3>=0.7,"Needs Monitoring","Poor")) -> Good | X3: Ghost
A4: 45867 | B4: =NETWORKDAYS.INTL(A5,TODAY(),11) -> 461 | C4: 6000000 | D4: 10000 | E4: =D4*6 -> 60000 | F4: 50000 | G4: =B4*D4 -> 4610000 | H4: MOVE1000002 | I4: Frozen | J4: EKY29CD | K4: Victor Eze | L4: 1000000002 | M4: 3656796 | N4: 0 | O4: =G4-M4 -> 953204 | P4: =C4-M4 -> 2343204 | Q4: =IF(O4>15000,"Non-compliant","Compliant") -> Non-compliant | R4: Festac | S4: =M4/C4 -> 0.609466 | T4: =M4/G4 -> 0.79323124 | U4: =N4/E4 -> 0 | V4: =O4/D4 -> 95.3204 | W4: =IF(T4>=0.9,"Good",IF(T4>=0.7,"Needs Monitoring","Poor")) -> Needs Monitoring | X4: Original
A5: 45741 | B5: =NETWORKDAYS.INTL(A6,TODAY(),11) -> 344 | C5: 6000000 | D5: 10000 | E5: =D5*6 -> 60000 | F5: 75000 | G5: =B5*D5 -> 3440000 | H5: MOVE1000003 | I5: Active | J5: APP78AB | K5: Musa Bello | L5: 1000000003 | M5: 2946949 | N5: 70000 | O5: =G5-M5 -> 493051 | P5: =C5-M5 -> 3053051 | Q5: =IF(O5>15000,"Non-compliant","Compliant") -> Non-compliant | R5: Festac | S5: =M5/C5 -> 0.49115817 | T5: =M5/G5 -> 0.85667122 | U5: =N5/E5 -> 1.1666667 | V5: =O5/D5 -> 49.3051 | W5: =IF(T5>=0.9,"Good",IF(T5>=0.7,"Needs Monitoring","Poor")) -> Needs Monitoring | X5: Original
A6: 45877 | B6: =NETWORKDAYS.INTL(A7,TODAY(),11) -> 382 | C6: 6000000 | D6: 10000 | E6: =D6*6 -> 60000 | F6: 100000 | G6: =B6*D6 -> 3820000 | H6: MOVE1000004 | I6: Active | J6: LAG47AB | K6: Tunde Eze | L6: 1000000004 | M6: 3454652 | N6: 36500 | O6: =G6-M6 -> 365348 | P6: =C6-M6 -> 2545348 | Q6: =IF(O6>15000,"Non-compliant","Compliant") -> Non-compliant | R6: Festac | S6: =M6/C6 -> 0.57577533 | T6: =M6/G6 -> 0.90435916 | U6: =N6/E6 -> 0.60833333 | V6: =O6/D6 -> 36.5348 | W6: =IF(T6>=0.9,"Good",IF(T6>=0.7,"Needs Monitoring","Poor")) -> Good | X6: Ghost
A7: 45833 | B7: =NETWORKDAYS.INTL(A8,TODAY(),11) -> 446 | C7: 6000000 | D7: 10000 | E7: =D7*6 -> 60000 | F7: 50000 | G7: =B7*D7 -> 4460000 | H7: MOVE1000005 | I7: Active | J7: KTU87LM | K7: Daniel Ogunleye | L7: 1000000005 | M7: 3837891 | N7: 41500 | O7: =G7-M7 -> 622109 | P7: =C7-M7 -> 2162109 | Q7: =IF(O7>15000,"Non-compliant","Compliant") -> Non-compliant | R7: Festac | S7: =M7/C7 -> 0.6396485 | T7: =M7/G7 -> 0.86051368 | U7: =N7/E7 -> 0.69166667 | V7: =O7/D7 -> 62.2109 | W7: =IF(T7>=0.9,"Good",IF(T7>=0.7,"Needs Monitoring","Poor")) -> Needs Monitoring | X7: Original
A8: 45758 | B8: =NETWORKDAYS.INTL(A9,TODAY(),11) -> 468 | C8: 6000000 | D8: 11000 | E8: =D8*6 -> 66000 | F8: 75000 | G8: =B8*D8 -> 5148000 | H8: MOVE1000006 | I8: Active | J8: EKY17CD | K8: Chinedu Balogun | L8: 1000000006 | M8: 5418043 | N8: 44000 | O8: =G8-M8 -> -270043 | P8: =C8-M8 -> 581957 | Q8: =IF(O8>15000,"Non-compliant","Compliant") -> Compliant | R8: Festac | S8: =M8/C8 -> 0.90300717 | T8: =M8/G8 -> 1.0524559 | U8: =N8/E8 -> 0.66666667 | V8: =O8/D8 -> -24.549364 | W8: =IF(T8>=0.9,"Good",IF(T8>=0.7,"Needs Monitoring","Poor")) -> Good | X8: Ghost
A9: 45733 | B9: =NETWORKDAYS.INTL(A10,TODAY(),11) -> 359 | C9: 6000000 | D9: 9000 | E9: =D9*6 -> 54000 | F9: 100000 | G9: =B9*D9 -> 3231000 | H9: MOVE1000007 | I9: Frozen | J9: APP92GH | K9: Samuel Akinyemi | L9: 1000000007 | M9: 3490896 | N9: 0 | O9: =G9-M9 -> -259896 | P9: =C9-M9 -> 2509104 | Q9: =IF(O9>15000,"Non-compliant","Compliant") -> Compliant | R9: Festac | S9: =M9/C9 -> 0.581816 | T9: =M9/G9 -> 1.0804383 | U9: =N9/E9 -> 0 | V9: =O9/D9 -> -28.877333 | W9: =IF(T9>=0.9,"Good",IF(T9>=0.7,"Needs Monitoring","Poor")) -> Good | X9: Ghost
A10: 45860 | B10: =NETWORKDAYS.INTL(A11,TODAY(),11) -> 344 | C10: 6000000 | D10: 10000 | E10: =D10*6 -> 60000 | F10: 100000 | G10: =B10*D10 -> 3440000 | H10: MOVE1000008 | I10: Active | J10: EKY38CD | K10: Bright Sule | L10: 1000000008 | M10: 3329579 | N10: 57500 | O10: =G10-M10 -> 110421 | P10: =C10-M10 -> 2670421 | Q10: =IF(O10>15000,"Non-compliant","Compliant") -> Non-compliant | R10: Festac | S10: =M10/C10 -> 0.55492983 | T10: =M10/G10 -> 0.96790087 | U10: =N10/E10 -> 0.95833333 | V10: =O10/D10 -> 11.0421 | W10: =IF(T10>=0.9,"Good",IF(T10>=0.7,"Needs Monitoring","Poor")) -> Good | X10: Original
A11: 45877 | B11: =NETWORKDAYS.INTL(A12,TODAY(),11) -> 456 | C11: 6000000 | D11: 9000 | E11: =D11*6 -> 54000 | F11: 100000 | G11: =B11*D11 -> 4104000 | H11: MOVE1000009 | I11: Active | J11: APP86GH | K11: Bright Akinyemi | L11: 1000000009 | M11: 2919733 | N11: 37500 | O11: =G11-M11 -> 1184267 | P11: =C11-M11 -> 3080267 | Q11: =IF(O11>15000,"Non-compliant","Compliant") -> Non-compliant | R11: Festac | S11: =M11/C11 -> 0.48662217 | T11: =M11/G11 -> 0.71143592 | U11: =N11/E11 -> 0.69444444 | V11: =O11/D11 -> 131.58522 | W11: =IF(T11>=0.9,"Good",IF(T11>=0.7,"Needs Monitoring","Poor")) -> Needs Monitoring | X11: Original
A12: 45746 | B12: =NETWORKDAYS.INTL(A13,TODAY(),11) -> 371 | C12: 6000000 | D12: 10000 | E12: =D12*6 -> 60000 | F12: 100000 | G12: =B12*D12 -> 3710000 | H12: MOVE1000010 | I12: Active | J12: LAG68AB | K12: Oluwaseun Okoro | L12: 1000000010 | M12: 5819111 | N12: 54000 | O12: =G12-M12 -> -2109111 | P12: =C12-M12 -> 180889 | Q12: =IF(O12>15000,"Non-compliant","Compliant") -> Compliant | R12: Festac | S12: =M12/C12 -> 0.96985183 | T12: =M12/G12 -> 1.5684935 | U12: =N12/E12 -> 0.9 | V12: =O12/D12 -> -210.9111 | W12: =IF(T12>=0.9,"Good",IF(T12>=0.7,"Needs Monitoring","Poor")) -> Good | X12: Ghost
A13: 45846 | B13: =NETWORKDAYS.INTL(A14,TODAY(),11) -> 411 | C13: 6000000 | D13: 10000 | E13: =D13*6 -> 60000 | F13: 100000 | G13: =B13*D13 -> 4110000 | H13: MOVE1000011 | I13: Active | J13: MUS35CD | K13: Godwin Johnson | L13: 1000000011 | M13: 3200100 | N13: 32500 | O13: =G13-M13 -> 909900 | P13: =C13-M13 -> 2799900 | Q13: =IF(O13>15000,"Non-compliant","Compliant") -> Non-compliant | R13: Festac | S13: =M13/C13 -> 0.53335 | T13: =M13/G13 -> 0.77861314 | U13: =N13/E13 -> 0.54166667 | V13: =O13/D13 -> 90.99 | W13: =IF(T13>=0.9,"Good",IF(T13>=0.7,"Needs Monitoring","Poor")) -> Needs Monitoring | X13: Original
... A150: 45767 | B150: =NETWORKDAYS.INTL(A151,TODAY(),11) -> 438 | C150: 6000000 | D150: 10000 | E150: =D150*6 -> 60000 | F150: 50000 | G150: =B150*D150 -> 4380000 | H150: MOVE1000148 | I150: Frozen | J150: MUS92CD | K150: Ayomide Madu | L150: 1000000148 | M150: 5130314 | N150: 0 | O150: =G150-M150 -> -750314 | P150: =C150-M150 -> 869686 | Q150: =IF(O150>15000,"Non-compliant","Compliant") -> Compliant | R150: Cele | S150: =M150/C150 -> 0.85505233 | T150: =M150/G150 -> 1.1713046 | U150: =N150/E150 -> 0 | V150: =O150/D150 -> -75.0314 | W150: =IF(T150>=0.9,"Good",IF(T150>=0.7,"Needs Monitoring","Poor")) -> Good | X150: Ghost
A151: 45767 | B151: 438 | C151: 6000000 | D151: 10000 | E151: =D151*6 -> 60000 | F151: 100000 | G151: =B151*D151 -> 4380000 | H151: MOVE1000149 | I151: Active | J151: KTU15LM | K151: Ayomide Akinyemi | L151: 1000000149 | M151: 3895698 | N151: 31500 | O151: =G151-M151 -> 484302 | P151: =C151-M151 -> 2104302 | Q151: =IF(O151>15000,"Non-compliant","Compliant") -> Non-compliant | R151: Cele | S151: =M151/C151 -> 0.649283 | T151: =M151/G151 -> 0.88942877 | U151: =N151/E151 -> 0.525 | V151: =O151/D151 -> 48.4302 | W151: =IF(T151>=0.9,"Good",IF(T151>=0.7,"Needs Monitoring","Poor")) -> Needs Monitoring | X151: Original

Sheet Analysis
A1: KPI | B1: Results
A2: =project_1_mobility_operations_d!C1 -> Total contract amount | B2: =SUM(project_1_mobility_operations_d!C2:C151) -> 900000000
A3: =project_1_mobility_operations_d!M1 -> Total Received | B3: =SUM(project_1_mobility_operations_d!M2:M151) -> 566243809
A4: Total Expected | B4: =SUM(project_1_mobility_operations_d!G2:G151) -> 602023000
A5: Total outstanding | B5: =SUM(project_1_mobility_operations_d!O2:O151) -> 35779191
A6: Collection rate | B6: =B3/B4 -> 0.9405684
A7: Collection progress | B7: =B3/B2 -> 0.62915979
A8: No of Original riders | B8: =COUNTIF(project_1_mobility_operations_d!X2:X151,"Original") -> 82
A9: No of Ghost riders | B9: =COUNTIF(project_1_mobility_operations_d!X2:X151,"Ghost") -> 68
A10: AVG Days behind | B10: =AVERAGE(project_1_mobility_operations_d!V2:V151) -> 23.630783
A11: Total assets | B11: =COUNTA(project_1_mobility_operations_d!H2:H151) -> 150
A13: Okota payment rate | B13: Results | D13: Festac Payment rate | E13: Results | G13: Cele payment rate
A14: Total contract amount | B14: =SUM(project_1_mobility_operations_d!C52:C101) -> 300000000 | D14: Total contract amount | E14: =SUM(project_1_mobility_operations_d!C2:C51) -> 300000000 | G14: Total contract amount | H14: =SUM(project_1_mobility_operations_d!C102:C151) -> 300000000
A15: Total expected | B15: =SUM(project_1_mobility_operations_d!G52:G101) -> 196680000 | D15: Total expected | E15: =SUM(project_1_mobility_operations_d!G2:G51) -> 201746000 | G15: Total expected | H15: =SUM(project_1_mobility_operations_d!G102:G151) -> 203597000
A16: Total Received | B16: =SUM(project_1_mobility_operations_d!M52:M101) -> 175144730 | D16: Total Received | E16: =SUM(project_1_mobility_operations_d!M2:M51) -> 194726856 | G16: Total Received | H16: =SUM(project_1_mobility_operations_d!M102:M151) -> 196372223
A17: Total outstanding | B17: =SUM(project_1_mobility_operations_d!O52:O101) -> 21535270 | D17: Total outstanding | E17: =SUM(project_1_mobility_operations_d!O2:O51) -> 7019144 | G17: Total outstanding | H17: =SUM(project_1_mobility_operations_d!O102:O151) -> 7224777
A18: Collection Rate | B18: =B16/B15 -> 0.89050605 | D18: Collection Rate | E18: =E16/E15 -> 0.96520801 | G18: Collection Rate | H18: =H16/H15 -> 0.96451432
A19: Collection Progress | B19: =B16/B14 -> 0.58381577 | D19: Collection Progress | E19: =E16/E14 -> 0.64908952 | G19: Collection Progress | H19: =H16/H14 -> 0.65457408

Sheet Pivot table
A3: Average of Payment rate | B3: Sum of Due today | C3: Sum of Total Received | D3: Sum of Outstanding
A4: 0.95302577 | B4: 602023000 | C4: 566243809 | D4: 35779191
A7: Row Labels | B7: Sum of Total Received | C7: Average of Payment rate | D7: Sum of Due today | E7: Sum of Outstanding | F7: Average of Days behind
A8: Cele | B8: 196372223 | C8: 0.98089467 | D8: 203597000 | E8: 7224777 | F8: 13.139747
A9: Festac | B9: 194726856 | C9: 0.97713938 | D9: 201746000 | E9: 7019144 | F9: 14.985771
A10: Okota | B10: 175144730 | C10: 0.90104326 | D10: 196680000 | E10: 21535270 | F10: 42.766832
A11: Grand Total | B11: 566243809 | C11: 0.95302577 | D11: 602023000 | E11: 35779191 | F11: 23.630783
B15: Row Labels | C15: Average of Payment rate
B16: Cele | C16: 0.98089467
B17: Festac | C17: 0.97713938
B18: Okota | C18: 0.90104326
B19: Grand Total | C19: 0.95302577
B31: Row Labels | C31: Total expected as of today | D31: Total Received as of today
B32: Cele | C32: 203597000 | D32: 196372223
B33: Festac | C33: 201746000 | D33: 194726856
B34: Okota | C34: 196680000 | D34: 175144730
A44: Rider status | B44: (All)
A45: Repayment performance Category | B45: Poor
A47: Row Labels | B47: Sum of Due today | C47: Sum of Total Received | D47: Sum of Outstanding | E47: Average of Days behind | F47: Average of Payment rate
A48: Cele | B48: 21883000 | C48: 12819045 | D48: 9063955 | E48: 178.67365 | F48: 0.58840311
A49: Emeka Okoro | B49: 4670000 | C49: 2233406 | D49: 2436594 | E49: 243.6594 | F49: 0.4782454
A50: Victor Eze | B50: 4500000 | C50: 2423590 | D50: 2076410 | E50: 207.641 | F50: 0.53857556
A51: Daniel Johnson | B51: 3910000 | C51: 2454832 | D51: 1455168 | E51: 145.5168 | F51: 0.62783427
A52: Yusuf Uche | B52: 4480000 | C52: 2817217 | D52: 1662783 | E52: 166.2783 | F52: 0.62884308
A53: Musa Williams | B53: 4323000 | C53: 2890000 | D53: 1433000 | E53: 130.27273 | F53: 0.66851723
A54: Festac | B54: 23103000 | C54: 14320345 | D54: 8782655 | E54: 172.84765 | F54: 0.62094224
A55: Musa Okafor | B55: 4810000 | C55: 2567845 | D55: 2242155 | E55: 224.2155 | F55: 0.53385551
A56: Yusuf Okoro | B56: 4620000 | C56: 2725337 | D56: 1894663 | E56: 189.4663 | F56: 0.58989978
A57: Tochukwu Bello | B57: 4740000 | C57: 3111227 | D57: 1628773 | E57: 162.8773 | F57: 0.656377
A58: Michael Okafor | B58: 4543000 | C58: 3000000 | D58: 1543000 | E58: 140.27273 | F58: 0.66035659
A59: Tunde Lawal | B59: 4390000 | C59: 2915936 | D59: 1474064 | E59: 147.4064 | F59: 0.66422232
... A71: Grand Total | B71: 88015000 | C71: 54525105 | D71: 33489895 | E71: 166.25405 | F71: 0.62088351
A122: Cele | B122: Average of Payment rate | C122: Average of Payment rate
A123: Emeka Okoro(Cele) | B123: 0.58840311 | C123: 0.58840311
A124: Festac
A125: Musa Okafor(Festac) | B125: 0.53385551 | C125: 0.53385551
A126: Okota
A127: Daniel Lawal(Okota) | B127: 0.5463447 | C127: 0.5463447
A130: Asset status | B130: Compliant
A131: Rider status | B131: (All)
...
